<?xml version="1.0" encoding="UTF-8"?>
<!-- Generated by org.testng.reporters.JUnitXMLReporter -->
<testsuite ignored="0" hostname="Tamerlan-ThinkPad" failures="2" tests="3" name="validTest" time="9.624" errors="0" timestamp="2020-07-21T12:16:25 EDT">
  <testcase classname="project.validateNavBarTest" name="home" time="0.427"/>
  <testcase classname="project.validateTitleTest" name="home" time="0.294">
    <failure type="java.lang.AssertionError" message="expected [Responding toto the Coronavirus] but found [Responding to the Coronavirus]">
      <![CDATA[java.lang.AssertionError: expected [Responding toto the Coronavirus] but found [Responding to the Coronavirus]
at project.validateTitleTest.home(validateTitleTest.java:30)
at java.base/java.util.ArrayList.forEach(ArrayList.java:1540)
at java.base/java.util.concurrent.FutureTask.run(FutureTask.java:264)
at java.base/java.util.concurrent.ThreadPoolExecutor.runWorker(ThreadPoolExecutor.java:1128)
at java.base/java.util.concurrent.ThreadPoolExecutor$Worker.run(ThreadPoolExecutor.java:628)
at java.base/java.lang.Thread.run(Thread.java:834)
... Removed 23 stack frames]]>
    </failure>
  </testcase> <!-- home -->
  <testcase classname="project.validateTitleTest" name="home" time="0.297">
    <failure type="java.lang.NullPointerException">
      <![CDATA[java.lang.NullPointerException
at project.base.getScreenShotPath(base.java:52)
at project.listeners.onTestFailure(listeners.java:30)
at java.base/java.util.ArrayList.forEach(ArrayList.java:1540)
at java.base/java.util.concurrent.FutureTask.run(FutureTask.java:264)
at java.base/java.util.concurrent.ThreadPoolExecutor.runWorker(ThreadPoolExecutor.java:1128)
at java.base/java.util.concurrent.ThreadPoolExecutor$Worker.run(ThreadPoolExecutor.java:628)
at java.base/java.lang.Thread.run(Thread.java:834)
... Removed 15 stack frames]]>
    </failure>
  </testcase> <!-- home -->
</testsuite> <!-- validTest -->
